[2024-01-23T18:29:56.983+0000] {taskinstance.py:1956} INFO - Dependencies all met for dep_context=non-requeueable deps ti=<TaskInstance: fetch_stackoverflow_data.transform_stackoverflow_data manual__2024-01-23T18:20:46.492577+00:00 [queued]>
[2024-01-23T18:29:57.020+0000] {taskinstance.py:1956} INFO - Dependencies all met for dep_context=requeueable deps ti=<TaskInstance: fetch_stackoverflow_data.transform_stackoverflow_data manual__2024-01-23T18:20:46.492577+00:00 [queued]>
[2024-01-23T18:29:57.023+0000] {taskinstance.py:2170} INFO - Starting attempt 2 of 6
[2024-01-23T18:29:57.075+0000] {taskinstance.py:2191} INFO - Executing <Task(PythonOperator): transform_stackoverflow_data> on 2024-01-23 18:20:46.492577+00:00
[2024-01-23T18:29:57.098+0000] {standard_task_runner.py:60} INFO - Started process 3514 to run task
[2024-01-23T18:29:57.112+0000] {standard_task_runner.py:87} INFO - Running: ['***', 'tasks', 'run', 'fetch_stackoverflow_data', 'transform_stackoverflow_data', 'manual__2024-01-23T18:20:46.492577+00:00', '--job-id', '395', '--raw', '--subdir', 'DAGS_FOLDER/loading_data_to_aws_S3.py', '--cfg-path', '/tmp/tmplkiz1d4g']
[2024-01-23T18:29:57.116+0000] {standard_task_runner.py:88} INFO - Job 395: Subtask transform_stackoverflow_data
[2024-01-23T18:29:57.375+0000] {task_command.py:423} INFO - Running <TaskInstance: fetch_stackoverflow_data.transform_stackoverflow_data manual__2024-01-23T18:20:46.492577+00:00 [running]> on host 9924936b75b5
[2024-01-23T18:29:57.831+0000] {taskinstance.py:2480} INFO - Exporting env vars: AIRFLOW_CTX_DAG_OWNER='charlotte' AIRFLOW_CTX_DAG_ID='fetch_stackoverflow_data' AIRFLOW_CTX_TASK_ID='transform_stackoverflow_data' AIRFLOW_CTX_EXECUTION_DATE='2024-01-23T18:20:46.492577+00:00' AIRFLOW_CTX_TRY_NUMBER='2' AIRFLOW_CTX_DAG_RUN_ID='manual__2024-01-23T18:20:46.492577+00:00'
[2024-01-23T18:29:57.836+0000] {taskinstance.py:2698} ERROR - Task failed with exception
Traceback (most recent call last):
  File "/home/airflow/.local/lib/python3.8/site-packages/airflow/models/taskinstance.py", line 433, in _execute_task
    result = execute_callable(context=context, **execute_callable_kwargs)
  File "/home/airflow/.local/lib/python3.8/site-packages/airflow/operators/python.py", line 199, in execute
    return_value = self.execute_callable()
  File "/home/airflow/.local/lib/python3.8/site-packages/airflow/operators/python.py", line 216, in execute_callable
    return self.python_callable(*self.op_args, **self.op_kwargs)
  File "/opt/airflow/dags/loading_data_to_aws_S3.py", line 19, in transform_data
    response = ti.xcom_pull('fetch_stackoverflow_data', task_id ='get_stackoverflow_data')
  File "/home/airflow/.local/lib/python3.8/site-packages/airflow/utils/session.py", line 79, in wrapper
    return func(*args, session=session, **kwargs)
TypeError: xcom_pull() got an unexpected keyword argument 'task_id'
[2024-01-23T18:29:57.859+0000] {taskinstance.py:1138} INFO - Marking task as UP_FOR_RETRY. dag_id=fetch_stackoverflow_data, task_id=transform_stackoverflow_data, execution_date=20240123T182046, start_date=20240123T182956, end_date=20240123T182957
[2024-01-23T18:29:57.888+0000] {standard_task_runner.py:107} ERROR - Failed to execute job 395 for task transform_stackoverflow_data (xcom_pull() got an unexpected keyword argument 'task_id'; 3514)
[2024-01-23T18:29:57.927+0000] {local_task_job_runner.py:234} INFO - Task exited with return code 1
[2024-01-23T18:29:57.972+0000] {taskinstance.py:3280} INFO - 0 downstream tasks scheduled from follow-on schedule check
