[2024-01-23T18:04:25.652+0000] {taskinstance.py:1956} INFO - Dependencies all met for dep_context=non-requeueable deps ti=<TaskInstance: fetch_stackoverflow_data.transform_stackoverflow_data manual__2024-01-23T17:58:54.054866+00:00 [queued]>
[2024-01-23T18:04:25.671+0000] {taskinstance.py:1956} INFO - Dependencies all met for dep_context=requeueable deps ti=<TaskInstance: fetch_stackoverflow_data.transform_stackoverflow_data manual__2024-01-23T17:58:54.054866+00:00 [queued]>
[2024-01-23T18:04:25.672+0000] {taskinstance.py:2170} INFO - Starting attempt 2 of 6
[2024-01-23T18:04:25.691+0000] {taskinstance.py:2191} INFO - Executing <Task(PythonOperator): transform_stackoverflow_data> on 2024-01-23 17:58:54.054866+00:00
[2024-01-23T18:04:25.698+0000] {standard_task_runner.py:60} INFO - Started process 2559 to run task
[2024-01-23T18:04:25.703+0000] {standard_task_runner.py:87} INFO - Running: ['***', 'tasks', 'run', 'fetch_stackoverflow_data', 'transform_stackoverflow_data', 'manual__2024-01-23T17:58:54.054866+00:00', '--job-id', '281', '--raw', '--subdir', 'DAGS_FOLDER/loading_data_to_aws_S3.py', '--cfg-path', '/tmp/tmpsjjrzahz']
[2024-01-23T18:04:25.708+0000] {standard_task_runner.py:88} INFO - Job 281: Subtask transform_stackoverflow_data
[2024-01-23T18:04:25.775+0000] {task_command.py:423} INFO - Running <TaskInstance: fetch_stackoverflow_data.transform_stackoverflow_data manual__2024-01-23T17:58:54.054866+00:00 [running]> on host 9924936b75b5
[2024-01-23T18:04:25.878+0000] {taskinstance.py:2480} INFO - Exporting env vars: AIRFLOW_CTX_DAG_OWNER='charlotte' AIRFLOW_CTX_DAG_ID='fetch_stackoverflow_data' AIRFLOW_CTX_TASK_ID='transform_stackoverflow_data' AIRFLOW_CTX_EXECUTION_DATE='2024-01-23T17:58:54.054866+00:00' AIRFLOW_CTX_TRY_NUMBER='2' AIRFLOW_CTX_DAG_RUN_ID='manual__2024-01-23T17:58:54.054866+00:00'
[2024-01-23T18:04:25.881+0000] {taskinstance.py:2698} ERROR - Task failed with exception
Traceback (most recent call last):
  File "/home/airflow/.local/lib/python3.8/site-packages/airflow/models/taskinstance.py", line 433, in _execute_task
    result = execute_callable(context=context, **execute_callable_kwargs)
  File "/home/airflow/.local/lib/python3.8/site-packages/airflow/operators/python.py", line 199, in execute
    return_value = self.execute_callable()
  File "/home/airflow/.local/lib/python3.8/site-packages/airflow/operators/python.py", line 216, in execute_callable
    return self.python_callable(*self.op_args, **self.op_kwargs)
  File "/opt/airflow/dags/loading_data_to_aws_S3.py", line 19, in transform_data
    response = ti.xcom_pull('fetch_stackoverflow_data', task_ids='get_stackoverflow_data')
  File "/home/airflow/.local/lib/python3.8/site-packages/airflow/utils/session.py", line 79, in wrapper
    return func(*args, session=session, **kwargs)
TypeError: xcom_pull() got multiple values for argument 'task_ids'
[2024-01-23T18:04:25.891+0000] {taskinstance.py:1138} INFO - Marking task as UP_FOR_RETRY. dag_id=fetch_stackoverflow_data, task_id=transform_stackoverflow_data, execution_date=20240123T175854, start_date=20240123T180425, end_date=20240123T180425
[2024-01-23T18:04:25.911+0000] {standard_task_runner.py:107} ERROR - Failed to execute job 281 for task transform_stackoverflow_data (xcom_pull() got multiple values for argument 'task_ids'; 2559)
[2024-01-23T18:04:25.959+0000] {local_task_job_runner.py:234} INFO - Task exited with return code 1
[2024-01-23T18:04:25.988+0000] {taskinstance.py:3280} INFO - 0 downstream tasks scheduled from follow-on schedule check
