[2024-01-23T18:34:41.741+0000] {taskinstance.py:1956} INFO - Dependencies all met for dep_context=non-requeueable deps ti=<TaskInstance: fetch_stackoverflow_data.transform_stackoverflow_data manual__2024-01-23T18:09:38.759901+00:00 [queued]>
[2024-01-23T18:34:41.752+0000] {taskinstance.py:1956} INFO - Dependencies all met for dep_context=requeueable deps ti=<TaskInstance: fetch_stackoverflow_data.transform_stackoverflow_data manual__2024-01-23T18:09:38.759901+00:00 [queued]>
[2024-01-23T18:34:41.753+0000] {taskinstance.py:2170} INFO - Starting attempt 3 of 6
[2024-01-23T18:34:41.769+0000] {taskinstance.py:2191} INFO - Executing <Task(PythonOperator): transform_stackoverflow_data> on 2024-01-23 18:09:38.759901+00:00
[2024-01-23T18:34:41.776+0000] {standard_task_runner.py:60} INFO - Started process 3670 to run task
[2024-01-23T18:34:41.781+0000] {standard_task_runner.py:87} INFO - Running: ['***', 'tasks', 'run', 'fetch_stackoverflow_data', 'transform_stackoverflow_data', 'manual__2024-01-23T18:09:38.759901+00:00', '--job-id', '409', '--raw', '--subdir', 'DAGS_FOLDER/loading_data_to_aws_S3.py', '--cfg-path', '/tmp/tmp9rd2k2pm']
[2024-01-23T18:34:41.784+0000] {standard_task_runner.py:88} INFO - Job 409: Subtask transform_stackoverflow_data
[2024-01-23T18:34:41.839+0000] {task_command.py:423} INFO - Running <TaskInstance: fetch_stackoverflow_data.transform_stackoverflow_data manual__2024-01-23T18:09:38.759901+00:00 [running]> on host 9924936b75b5
[2024-01-23T18:34:41.932+0000] {taskinstance.py:2480} INFO - Exporting env vars: AIRFLOW_CTX_DAG_OWNER='charlotte' AIRFLOW_CTX_DAG_ID='fetch_stackoverflow_data' AIRFLOW_CTX_TASK_ID='transform_stackoverflow_data' AIRFLOW_CTX_EXECUTION_DATE='2024-01-23T18:09:38.759901+00:00' AIRFLOW_CTX_TRY_NUMBER='3' AIRFLOW_CTX_DAG_RUN_ID='manual__2024-01-23T18:09:38.759901+00:00'
[2024-01-23T18:34:41.956+0000] {taskinstance.py:2698} ERROR - Task failed with exception
Traceback (most recent call last):
  File "/home/airflow/.local/lib/python3.8/site-packages/airflow/models/taskinstance.py", line 433, in _execute_task
    result = execute_callable(context=context, **execute_callable_kwargs)
  File "/home/airflow/.local/lib/python3.8/site-packages/airflow/operators/python.py", line 199, in execute
    return_value = self.execute_callable()
  File "/home/airflow/.local/lib/python3.8/site-packages/airflow/operators/python.py", line 216, in execute_callable
    return self.python_callable(*self.op_args, **self.op_kwargs)
  File "/opt/airflow/dags/loading_data_to_aws_S3.py", line 21, in transform_data
    df=df.drop(['has_synonyms','is_moder ator_only', 'is_required'], axis = 1)
  File "/home/airflow/.local/lib/python3.8/site-packages/pandas/core/frame.py", line 5258, in drop
    return super().drop(
  File "/home/airflow/.local/lib/python3.8/site-packages/pandas/core/generic.py", line 4549, in drop
    obj = obj._drop_axis(labels, axis, level=level, errors=errors)
  File "/home/airflow/.local/lib/python3.8/site-packages/pandas/core/generic.py", line 4591, in _drop_axis
    new_axis = axis.drop(labels, errors=errors)
  File "/home/airflow/.local/lib/python3.8/site-packages/pandas/core/indexes/base.py", line 6699, in drop
    raise KeyError(f"{list(labels[mask])} not found in axis")
KeyError: "['is_moder ator_only'] not found in axis"
[2024-01-23T18:34:41.972+0000] {taskinstance.py:1138} INFO - Marking task as UP_FOR_RETRY. dag_id=fetch_stackoverflow_data, task_id=transform_stackoverflow_data, execution_date=20240123T180938, start_date=20240123T183441, end_date=20240123T183441
[2024-01-23T18:34:41.986+0000] {standard_task_runner.py:107} ERROR - Failed to execute job 409 for task transform_stackoverflow_data ("['is_moder ator_only'] not found in axis"; 3670)
[2024-01-23T18:34:41.995+0000] {local_task_job_runner.py:234} INFO - Task exited with return code 1
[2024-01-23T18:34:42.030+0000] {taskinstance.py:3280} INFO - 0 downstream tasks scheduled from follow-on schedule check
